2025-02-22 20:52:00,298 ERROR scheduler Exception in Enqueue Events for Site kigen.local
Traceback (most recent call last):
  File "/Users/cosmaskiplagat/DEV/develop/frappe-bench/apps/frappe/frappe/utils/scheduler.py", line 124, in enqueue_events_for_site
    if is_scheduler_inactive():
       ~~~~~~~~~~~~~~~~~~~~~^^
  File "/Users/cosmaskiplagat/DEV/develop/frappe-bench/apps/frappe/frappe/utils/scheduler.py", line 168, in is_scheduler_inactive
    if is_scheduler_disabled(verbose=verbose):
       ~~~~~~~~~~~~~~~~~~~~~^^^^^^^^^^^^^^^^^
  File "/Users/cosmaskiplagat/DEV/develop/frappe-bench/apps/frappe/frappe/utils/scheduler.py", line 181, in is_scheduler_disabled
    frappe.db.get_single_value("System Settings", "enable_scheduler")
    ~~~~~~~~~~~~~~~~~~~~~~~~~~^^^^^^^^^^^^^^^^^^^^^^^^^^^^^^^^^^^^^^^
  File "/Users/cosmaskiplagat/DEV/develop/frappe-bench/apps/frappe/frappe/database/database.py", line 869, in get_single_value
    ).run()
      ~~~^^
  File "/Users/cosmaskiplagat/DEV/develop/frappe-bench/apps/frappe/frappe/query_builder/utils.py", line 84, in execute_query
    result = frappe.db.sql(query, params, *args, **kwargs)  # nosemgrep
  File "/Users/cosmaskiplagat/DEV/develop/frappe-bench/apps/frappe/frappe/database/database.py", line 215, in sql
    self.connect()
    ~~~~~~~~~~~~^^
  File "/Users/cosmaskiplagat/DEV/develop/frappe-bench/apps/frappe/frappe/database/database.py", line 120, in connect
    self._conn: MariadbConnection | PostgresConnection = self.get_connection()
                                                         ~~~~~~~~~~~~~~~~~~~^^
  File "/Users/cosmaskiplagat/DEV/develop/frappe-bench/apps/frappe/frappe/database/mariadb/database.py", line 107, in get_connection
    conn = self._get_connection()
  File "/Users/cosmaskiplagat/DEV/develop/frappe-bench/apps/frappe/frappe/database/mariadb/database.py", line 113, in _get_connection
    return self.create_connection()
           ~~~~~~~~~~~~~~~~~~~~~~^^
  File "/Users/cosmaskiplagat/DEV/develop/frappe-bench/apps/frappe/frappe/database/mariadb/database.py", line 116, in create_connection
    return pymysql.connect(**self.get_connection_settings())
           ~~~~~~~~~~~~~~~^^^^^^^^^^^^^^^^^^^^^^^^^^^^^^^^^^
  File "/Users/cosmaskiplagat/DEV/develop/frappe-bench/env/lib/python3.13/site-packages/pymysql/connections.py", line 361, in __init__
    self.connect()
    ~~~~~~~~~~~~^^
  File "/Users/cosmaskiplagat/DEV/develop/frappe-bench/env/lib/python3.13/site-packages/pymysql/connections.py", line 669, in connect
    self._request_authentication()
    ~~~~~~~~~~~~~~~~~~~~~~~~~~~~^^
  File "/Users/cosmaskiplagat/DEV/develop/frappe-bench/env/lib/python3.13/site-packages/pymysql/connections.py", line 957, in _request_authentication
    auth_packet = self._read_packet()
  File "/Users/cosmaskiplagat/DEV/develop/frappe-bench/env/lib/python3.13/site-packages/pymysql/connections.py", line 775, in _read_packet
    packet.raise_for_error()
    ~~~~~~~~~~~~~~~~~~~~~~^^
  File "/Users/cosmaskiplagat/DEV/develop/frappe-bench/env/lib/python3.13/site-packages/pymysql/protocol.py", line 219, in raise_for_error
    err.raise_mysql_exception(self._data)
    ~~~~~~~~~~~~~~~~~~~~~~~~~^^^^^^^^^^^^
  File "/Users/cosmaskiplagat/DEV/develop/frappe-bench/env/lib/python3.13/site-packages/pymysql/err.py", line 150, in raise_mysql_exception
    raise errorclass(errno, errval)
pymysql.err.OperationalError: (1045, "Access denied for user '_f82a817be57428d3'@'localhost' (using password: YES)")
